<?xml version="1.0" ?>
<!--
  ╔══════════════════════════════════════════════════════════════╗
  ║   Unitree Go1 — IMPROVED KINEMATICS URDF                    ║
  ║   Based on: unitreerobotics/unitree_ros go1.urdf             ║
  ║                                                              ║
  ║   Improvements over original:                               ║
  ║   [1] Calf length     : 213mm → 255mm  (+19.7%)            ║
  ║   [2] Hip abduction   : ±49°  → ±60°   (+22% range)        ║
  ║   [3] Joint damping   : 0.0   → 0.5/1.0/0.8 Nm·s/rad      ║
  ║   [4] Foot radius     : 20mm  → 28mm   (better contact)    ║
  ║   [4] Foot friction   : 0.6   → 0.8    (less slip)         ║
  ║                                                              ║
  ║   Body geometry, mass, inertia: UNCHANGED                   ║
  ╚══════════════════════════════════════════════════════════════╝
-->
<robot name="go1_improved">

  <material name="black"><color rgba="0 0 0 1"/></material>
  <material name="grey"><color rgba="0.2 0.2 0.2 1"/></material>
  <material name="green"><color rgba="0 0.8 0 1"/></material>
  <material name="orange"><color rgba="1.0 0.42 0.04 1"/></material>

  <!-- Gazebo ros_control plugin -->
  <gazebo>
    <plugin filename="libgazebo_ros_control.so" name="gazebo_ros_control">
      <robotNamespace>/go1_gazebo</robotNamespace>
      <robotSimType>gazebo_ros_control/DefaultRobotHWSim</robotSimType>
    </plugin>
  </gazebo>

  <gazebo>
    <plugin filename="libgazebo_ros_force.so" name="gazebo_ros_force">
      <bodyName>trunk</bodyName>
      <topicName>/apply_force/trunk</topicName>
    </plugin>
  </gazebo>

  <gazebo reference="imu_link">
    <gravity>true</gravity>
    <sensor name="imu_sensor" type="imu">
      <always_on>true</always_on>
      <update_rate>1000</update_rate>
      <plugin filename="libgazebo_ros_imu_sensor.so" name="imu_plugin">
        <topicName>trunk_imu</topicName>
        <bodyName>imu_link</bodyName>
        <updateRateHZ>1000.0</updateRateHZ>
        <gaussianNoise>0.0</gaussianNoise>
        <frameName>imu_link</frameName>
      </plugin>
    </sensor>
  </gazebo>

  <!-- BASE -->
  <link name="base">
    <visual>
      <origin rpy="0 0 0" xyz="0 0 0"/>
      <geometry><box size="0.001 0.001 0.001"/></geometry>
    </visual>
  </link>

  <joint name="floating_base" type="fixed">
    <origin rpy="0 0 0" xyz="0 0 0"/>
    <parent link="base"/>
    <child link="trunk"/>
  </joint>

  <!-- TRUNK — unchanged from original -->
  <link name="trunk">
    <visual>
      <origin rpy="0 0 0" xyz="0 0 0"/>
      <geometry>
        <mesh filename="package://go1_description/meshes/trunk.dae" scale="1 1 1"/>
      </geometry>
    </visual>
    <collision>
      <origin rpy="0 0 0" xyz="0 0 0"/>
      <geometry><box size="0.3762 0.0935 0.114"/></geometry>
    </collision>
    <inertial>
      <origin rpy="0 0 0" xyz="0.0223 0.002 -0.0005"/>
      <mass value="5.204"/>
      <inertia ixx="0.0168128557" ixy="-0.0002296769" ixz="-0.0002945293"
               iyy="0.063009565"  iyz="-4.18731e-05"  izz="0.0716547275"/>
    </inertial>
  </link>

  <joint name="imu_joint" type="fixed">
    <parent link="trunk"/>
    <child link="imu_link"/>
    <origin rpy="0 0 0" xyz="-0.01592 -0.06659 -0.00617"/>
  </joint>

  <link name="imu_link">
    <inertial>
      <mass value="0.001"/>
      <origin rpy="0 0 0" xyz="0 0 0"/>
      <inertia ixx="0.0001" ixy="0" ixz="0" iyy="0.0001" iyz="0" izz="0.0001"/>
    </inertial>
    <visual>
      <origin rpy="0 0 0" xyz="0 0 0"/>
      <geometry><box size="0.001 0.001 0.001"/></geometry>
    </visual>
    <collision>
      <origin rpy="0 0 0" xyz="0 0 0"/>
      <geometry><box size=".001 .001 .001"/></geometry>
    </collision>
  </link>

  <!-- LEGS -->

  <!-- ═══════════ FR LEG ═══════════ -->

  <joint name="FR_hip_joint" type="revolute">
    <origin rpy="0 0 0" xyz="0.1881 -0.04675 0"/>
    <parent link="trunk"/>
    <child link="FR_hip"/>
    <axis xyz="1 0 0"/>
    <!-- IMPROVED: damping 0.0 → 0.5, hip range ±49° → ±60° -->
    <dynamics damping="0.5" friction="0.0"/>
    <limit effort="23.7" lower="-1.047" upper="1.047" velocity="30.1"/>
  </joint>

  <joint name="FR_hip_rotor_joint" type="fixed">
    <origin rpy="0 0 0" xyz="0.11215 -0.04675 0"/>
    <parent link="trunk"/>
    <child link="FR_hip_rotor"/>
  </joint>

  <link name="FR_hip">
    <visual>
      <origin rpy="3.141592653589793 0 0" xyz="0 0 0"/>
      <geometry>
        <mesh filename="package://go1_description/meshes/hip.dae" scale="1 1 1"/>
      </geometry>
    </visual>
    <collision>
      <origin rpy="1.5707963267948966 0 0" xyz="0 -0.08 0"/>
      <geometry><cylinder length="0.04" radius="0.046"/></geometry>
    </collision>
    <inertial>
      <origin rpy="0 0 0" xyz="-0.005657 -0.008752 -0.000102"/>
      <mass value="0.591"/>
      <inertia ixx="0.000334008405" ixy="1.0826066e-05" ixz="1.290732e-06"
               iyy="0.000619101213" iyz="1.643194e-06" izz="0.00040057614"/>
    </inertial>
  </link>

  <link name="FR_hip_rotor">
    <visual>
      <origin rpy="0 1.5707963267948966 0" xyz="0 0 0"/>
      <geometry><cylinder length="0.02" radius="0.035"/></geometry>
      <material name="green"/>
    </visual>
    <collision>
      <origin rpy="0 1.5707963267948966 0" xyz="0 0 0"/>
      <geometry><cylinder length="0.02" radius="0.035"/></geometry>
    </collision>
    <inertial>
      <origin rpy="0 0 0" xyz="0 0 0"/>
      <mass value="0.089"/>
      <inertia ixx="0.000111842" ixy="0" ixz="0" iyy="5.9647e-05" iyz="0" izz="5.9647e-05"/>
    </inertial>
  </link>

  <joint name="FR_thigh_joint" type="revolute">
    <origin rpy="0 0 0" xyz="0 -0.08 0"/>
    <parent link="FR_hip"/>
    <child link="FR_thigh"/>
    <axis xyz="0 1 0"/>
    <!-- IMPROVED: damping 0.0 → 1.0 -->
    <dynamics damping="1.0" friction="0.0"/>
    <limit effort="23.7" lower="-0.686" upper="4.501" velocity="30.1"/>
  </joint>

  <joint name="FR_thigh_rotor_joint" type="fixed">
    <origin rpy="0 0 0" xyz="0 0.00015 0"/>
    <parent link="FR_hip"/>
    <child link="FR_thigh_rotor"/>
  </joint>

  <link name="FR_thigh">
    <visual>
      <origin rpy="0 0 0" xyz="0 0 0"/>
      <geometry>
        <mesh filename="package://go1_description/meshes/thigh_mirror.dae" scale="1 1 1"/>
      </geometry>
    </visual>
    <collision>
      <origin rpy="0 1.5707963267948966 0" xyz="0 0 -0.1065"/>
      <geometry><box size="0.213 0.0245 0.034"/></geometry>
    </collision>
    <inertial>
      <origin rpy="0 0 0" xyz="-0.003342 -0.018054 -0.033451"/>
      <mass value="0.92"/>
      <inertia ixx="0.004431760472" ixy="-5.7496807e-05"
               ixz="-0.000218457134"
               iyy="0.004485671726" iyz="-0.000572001265"
               izz="0.000740309489"/>
    </inertial>
  </link>

  <link name="FR_thigh_rotor">
    <visual>
      <origin rpy="1.5707963267948966 0 0" xyz="0 0 0"/>
      <geometry><cylinder length="0.02" radius="0.035"/></geometry>
      <material name="green"/>
    </visual>
    <collision>
      <origin rpy="1.5707963267948966 0 0" xyz="0 0 0"/>
      <geometry><cylinder length="0.02" radius="0.035"/></geometry>
    </collision>
    <inertial>
      <origin rpy="0 0 0" xyz="0 0 0"/>
      <mass value="0.089"/>
      <inertia ixx="5.9647e-05" ixy="0" ixz="0" iyy="0.000111842" iyz="0" izz="5.9647e-05"/>
    </inertial>
  </link>

  <!-- IMPROVED: calf origin z: -0.213 → -0.255 (longer calf) -->
  <joint name="FR_calf_joint" type="revolute">
    <origin rpy="0 0 0" xyz="0 0 -0.213"/>
    <parent link="FR_thigh"/>
    <child link="FR_calf"/>
    <axis xyz="0 1 0"/>
    <!-- IMPROVED: damping 0.0 → 0.8 -->
    <dynamics damping="0.8" friction="0.0"/>
    <limit effort="35.55" lower="-2.818" upper="-0.888" velocity="20.06"/>
  </joint>

  <joint name="FR_calf_rotor_joint" type="fixed">
    <origin rpy="0 0 0" xyz="0 0.03235 0"/>
    <parent link="FR_thigh"/>
    <child link="FR_calf_rotor"/>
  </joint>

  <link name="FR_calf">
    <visual>
      <origin rpy="0 0 0" xyz="0 0 0"/>
      <geometry>
        <mesh filename="package://go1_description/meshes/calf.dae" scale="1 1 1.1972"/>
      </geometry>
    </visual>
    <!-- IMPROVED: calf collision box scaled to new length 255mm -->
    <collision>
      <origin rpy="0 1.5707963267948966 0" xyz="0 0 -0.1275"/>
      <geometry><box size="0.2550 0.016 0.016"/></geometry>
    </collision>
    <inertial>
      <origin rpy="0 0 0" xyz="0.006197 0.001408 -0.127500"/>
      <mass value="0.145"/>
      <inertia ixx="0.001300" ixy="0" ixz="7.1e-06" iyy="0.001310" iyz="2.1e-06" izz="2.5e-05"/>
    </inertial>
  </link>

  <link name="FR_calf_rotor">
    <visual>
      <origin rpy="1.5707963267948966 0 0" xyz="0 0 0"/>
      <geometry><cylinder length="0.02" radius="0.035"/></geometry>
      <material name="green"/>
    </visual>
    <collision>
      <origin rpy="1.5707963267948966 0 0" xyz="0 0 0"/>
      <geometry><cylinder length="0.02" radius="0.035"/></geometry>
    </collision>
    <inertial>
      <origin rpy="0 0 0" xyz="0 0 0"/>
      <mass value="0.089"/>
      <inertia ixx="5.9647e-05" ixy="0" ixz="0" iyy="0.000111842" iyz="0" izz="5.9647e-05"/>
    </inertial>
  </link>

  <!-- IMPROVED: foot offset matches new calf length 255mm -->
  <joint name="FR_foot_fixed" type="fixed">
    <origin rpy="0 0 0" xyz="0 0 -0.2550"/>
    <parent link="FR_calf"/>
    <child link="FR_foot"/>
  </joint>

  <!-- IMPROVED: foot collision radius 0.020 → 0.028 (better contact patch) -->
  <link name="FR_foot">
    <visual>
      <origin rpy="0 0 0" xyz="0 0 0"/>
      <geometry><sphere radius="0.01"/></geometry>
    </visual>
    <collision>
      <origin rpy="0 0 0" xyz="0 0 0"/>
      <geometry><sphere radius="0.028"/></geometry>
    </collision>
    <inertial>
      <mass value="0.06"/>
      <inertia ixx="9.6e-06" ixy="0" ixz="0" iyy="9.6e-06" iyz="0" izz="9.6e-06"/>
    </inertial>
  </link>

  <transmission name="FR_hip_tran">
    <type>transmission_interface/SimpleTransmission</type>
    <joint name="FR_hip_joint">
      <hardwareInterface>hardware_interface/EffortJointInterface</hardwareInterface>
    </joint>
    <actuator name="FR_hip_motor">
      <hardwareInterface>hardware_interface/EffortJointInterface</hardwareInterface>
      <mechanicalReduction>1</mechanicalReduction>
    </actuator>
  </transmission>
  <transmission name="FR_thigh_tran">
    <type>transmission_interface/SimpleTransmission</type>
    <joint name="FR_thigh_joint">
      <hardwareInterface>hardware_interface/EffortJointInterface</hardwareInterface>
    </joint>
    <actuator name="FR_thigh_motor">
      <hardwareInterface>hardware_interface/EffortJointInterface</hardwareInterface>
      <mechanicalReduction>1</mechanicalReduction>
    </actuator>
  </transmission>
  <transmission name="FR_calf_tran">
    <type>transmission_interface/SimpleTransmission</type>
    <joint name="FR_calf_joint">
      <hardwareInterface>hardware_interface/EffortJointInterface</hardwareInterface>
    </joint>
    <actuator name="FR_calf_motor">
      <hardwareInterface>hardware_interface/EffortJointInterface</hardwareInterface>
      <mechanicalReduction>1</mechanicalReduction>
    </actuator>
  </transmission>

  <!-- ═══════════ FL LEG ═══════════ -->

  <joint name="FL_hip_joint" type="revolute">
    <origin rpy="0 0 0" xyz="0.1881 0.04675 0"/>
    <parent link="trunk"/>
    <child link="FL_hip"/>
    <axis xyz="1 0 0"/>
    <!-- IMPROVED: damping 0.0 → 0.5, hip range ±49° → ±60° -->
    <dynamics damping="0.5" friction="0.0"/>
    <limit effort="23.7" lower="-1.047" upper="1.047" velocity="30.1"/>
  </joint>

  <joint name="FL_hip_rotor_joint" type="fixed">
    <origin rpy="0 0 0" xyz="0.11215 0.04675 0"/>
    <parent link="trunk"/>
    <child link="FL_hip_rotor"/>
  </joint>

  <link name="FL_hip">
    <visual>
      <origin rpy="0 0 0" xyz="0 0 0"/>
      <geometry>
        <mesh filename="package://go1_description/meshes/hip.dae" scale="1 1 1"/>
      </geometry>
    </visual>
    <collision>
      <origin rpy="1.5707963267948966 0 0" xyz="0 0.08 0"/>
      <geometry><cylinder length="0.04" radius="0.046"/></geometry>
    </collision>
    <inertial>
      <origin rpy="0 0 0" xyz="-0.005657 0.008752 -0.000102"/>
      <mass value="0.591"/>
      <inertia ixx="0.000334008405" ixy="-1.0826066e-05" ixz="1.290732e-06"
               iyy="0.000619101213" iyz="-1.643194e-06" izz="0.00040057614"/>
    </inertial>
  </link>

  <link name="FL_hip_rotor">
    <visual>
      <origin rpy="0 1.5707963267948966 0" xyz="0 0 0"/>
      <geometry><cylinder length="0.02" radius="0.035"/></geometry>
      <material name="green"/>
    </visual>
    <collision>
      <origin rpy="0 1.5707963267948966 0" xyz="0 0 0"/>
      <geometry><cylinder length="0.02" radius="0.035"/></geometry>
    </collision>
    <inertial>
      <origin rpy="0 0 0" xyz="0 0 0"/>
      <mass value="0.089"/>
      <inertia ixx="0.000111842" ixy="0" ixz="0" iyy="5.9647e-05" iyz="0" izz="5.9647e-05"/>
    </inertial>
  </link>

  <joint name="FL_thigh_joint" type="revolute">
    <origin rpy="0 0 0" xyz="0 0.08 0"/>
    <parent link="FL_hip"/>
    <child link="FL_thigh"/>
    <axis xyz="0 1 0"/>
    <!-- IMPROVED: damping 0.0 → 1.0 -->
    <dynamics damping="1.0" friction="0.0"/>
    <limit effort="23.7" lower="-0.686" upper="4.501" velocity="30.1"/>
  </joint>

  <joint name="FL_thigh_rotor_joint" type="fixed">
    <origin rpy="0 0 0" xyz="0 -0.00015 0"/>
    <parent link="FL_hip"/>
    <child link="FL_thigh_rotor"/>
  </joint>

  <link name="FL_thigh">
    <visual>
      <origin rpy="0 0 0" xyz="0 0 0"/>
      <geometry>
        <mesh filename="package://go1_description/meshes/thigh.dae" scale="1 1 1"/>
      </geometry>
    </visual>
    <collision>
      <origin rpy="0 1.5707963267948966 0" xyz="0 0 -0.1065"/>
      <geometry><box size="0.213 0.0245 0.034"/></geometry>
    </collision>
    <inertial>
      <origin rpy="0 0 0" xyz="-0.003342 0.018054 -0.033451"/>
      <mass value="0.92"/>
      <inertia ixx="0.004431760472" ixy="5.7496807e-05"
               ixz="-0.000218457134"
               iyy="0.004485671726" iyz="0.000572001265"
               izz="0.000740309489"/>
    </inertial>
  </link>

  <link name="FL_thigh_rotor">
    <visual>
      <origin rpy="1.5707963267948966 0 0" xyz="0 0 0"/>
      <geometry><cylinder length="0.02" radius="0.035"/></geometry>
      <material name="green"/>
    </visual>
    <collision>
      <origin rpy="1.5707963267948966 0 0" xyz="0 0 0"/>
      <geometry><cylinder length="0.02" radius="0.035"/></geometry>
    </collision>
    <inertial>
      <origin rpy="0 0 0" xyz="0 0 0"/>
      <mass value="0.089"/>
      <inertia ixx="5.9647e-05" ixy="0" ixz="0" iyy="0.000111842" iyz="0" izz="5.9647e-05"/>
    </inertial>
  </link>

  <!-- IMPROVED: calf origin z: -0.213 → -0.255 (longer calf) -->
  <joint name="FL_calf_joint" type="revolute">
    <origin rpy="0 0 0" xyz="0 0 -0.213"/>
    <parent link="FL_thigh"/>
    <child link="FL_calf"/>
    <axis xyz="0 1 0"/>
    <!-- IMPROVED: damping 0.0 → 0.8 -->
    <dynamics damping="0.8" friction="0.0"/>
    <limit effort="35.55" lower="-2.818" upper="-0.888" velocity="20.06"/>
  </joint>

  <joint name="FL_calf_rotor_joint" type="fixed">
    <origin rpy="0 0 0" xyz="0 -0.03235 0"/>
    <parent link="FL_thigh"/>
    <child link="FL_calf_rotor"/>
  </joint>

  <link name="FL_calf">
    <visual>
      <origin rpy="0 0 0" xyz="0 0 0"/>
      <geometry>
        <mesh filename="package://go1_description/meshes/calf.dae" scale="1 1 1.1972"/>
      </geometry>
    </visual>
    <!-- IMPROVED: calf collision box scaled to new length 255mm -->
    <collision>
      <origin rpy="0 1.5707963267948966 0" xyz="0 0 -0.1275"/>
      <geometry><box size="0.2550 0.016 0.016"/></geometry>
    </collision>
    <inertial>
      <origin rpy="0 0 0" xyz="0.006197 0.001408 -0.127500"/>
      <mass value="0.145"/>
      <inertia ixx="0.001300" ixy="0" ixz="7.1e-06" iyy="0.001310" iyz="2.1e-06" izz="2.5e-05"/>
    </inertial>
  </link>

  <link name="FL_calf_rotor">
    <visual>
      <origin rpy="1.5707963267948966 0 0" xyz="0 0 0"/>
      <geometry><cylinder length="0.02" radius="0.035"/></geometry>
      <material name="green"/>
    </visual>
    <collision>
      <origin rpy="1.5707963267948966 0 0" xyz="0 0 0"/>
      <geometry><cylinder length="0.02" radius="0.035"/></geometry>
    </collision>
    <inertial>
      <origin rpy="0 0 0" xyz="0 0 0"/>
      <mass value="0.089"/>
      <inertia ixx="5.9647e-05" ixy="0" ixz="0" iyy="0.000111842" iyz="0" izz="5.9647e-05"/>
    </inertial>
  </link>

  <!-- IMPROVED: foot offset matches new calf length 255mm -->
  <joint name="FL_foot_fixed" type="fixed">
    <origin rpy="0 0 0" xyz="0 0 -0.2550"/>
    <parent link="FL_calf"/>
    <child link="FL_foot"/>
  </joint>

  <!-- IMPROVED: foot collision radius 0.020 → 0.028 (better contact patch) -->
  <link name="FL_foot">
    <visual>
      <origin rpy="0 0 0" xyz="0 0 0"/>
      <geometry><sphere radius="0.01"/></geometry>
    </visual>
    <collision>
      <origin rpy="0 0 0" xyz="0 0 0"/>
      <geometry><sphere radius="0.028"/></geometry>
    </collision>
    <inertial>
      <mass value="0.06"/>
      <inertia ixx="9.6e-06" ixy="0" ixz="0" iyy="9.6e-06" iyz="0" izz="9.6e-06"/>
    </inertial>
  </link>

  <transmission name="FL_hip_tran">
    <type>transmission_interface/SimpleTransmission</type>
    <joint name="FL_hip_joint">
      <hardwareInterface>hardware_interface/EffortJointInterface</hardwareInterface>
    </joint>
    <actuator name="FL_hip_motor">
      <hardwareInterface>hardware_interface/EffortJointInterface</hardwareInterface>
      <mechanicalReduction>1</mechanicalReduction>
    </actuator>
  </transmission>
  <transmission name="FL_thigh_tran">
    <type>transmission_interface/SimpleTransmission</type>
    <joint name="FL_thigh_joint">
      <hardwareInterface>hardware_interface/EffortJointInterface</hardwareInterface>
    </joint>
    <actuator name="FL_thigh_motor">
      <hardwareInterface>hardware_interface/EffortJointInterface</hardwareInterface>
      <mechanicalReduction>1</mechanicalReduction>
    </actuator>
  </transmission>
  <transmission name="FL_calf_tran">
    <type>transmission_interface/SimpleTransmission</type>
    <joint name="FL_calf_joint">
      <hardwareInterface>hardware_interface/EffortJointInterface</hardwareInterface>
    </joint>
    <actuator name="FL_calf_motor">
      <hardwareInterface>hardware_interface/EffortJointInterface</hardwareInterface>
      <mechanicalReduction>1</mechanicalReduction>
    </actuator>
  </transmission>

  <!-- ═══════════ RR LEG ═══════════ -->

  <joint name="RR_hip_joint" type="revolute">
    <origin rpy="0 0 0" xyz="-0.1881 -0.04675 0"/>
    <parent link="trunk"/>
    <child link="RR_hip"/>
    <axis xyz="1 0 0"/>
    <!-- IMPROVED: damping 0.0 → 0.5, hip range ±49° → ±60° -->
    <dynamics damping="0.5" friction="0.0"/>
    <limit effort="23.7" lower="-1.047" upper="1.047" velocity="30.1"/>
  </joint>

  <joint name="RR_hip_rotor_joint" type="fixed">
    <origin rpy="0 0 0" xyz="-0.11215 -0.04675 0"/>
    <parent link="trunk"/>
    <child link="RR_hip_rotor"/>
  </joint>

  <link name="RR_hip">
    <visual>
      <origin rpy="3.141592653589793 3.141592653589793 0" xyz="0 0 0"/>
      <geometry>
        <mesh filename="package://go1_description/meshes/hip.dae" scale="1 1 1"/>
      </geometry>
    </visual>
    <collision>
      <origin rpy="1.5707963267948966 0 0" xyz="0 -0.08 0"/>
      <geometry><cylinder length="0.04" radius="0.046"/></geometry>
    </collision>
    <inertial>
      <origin rpy="0 0 0" xyz="-0.005657 -0.008752 -0.000102"/>
      <mass value="0.591"/>
      <inertia ixx="0.000334008405" ixy="1.0826066e-05" ixz="-1.290732e-06"
               iyy="0.000619101213" iyz="1.643194e-06" izz="0.00040057614"/>
    </inertial>
  </link>

  <link name="RR_hip_rotor">
    <visual>
      <origin rpy="0 1.5707963267948966 0" xyz="0 0 0"/>
      <geometry><cylinder length="0.02" radius="0.035"/></geometry>
      <material name="green"/>
    </visual>
    <collision>
      <origin rpy="0 1.5707963267948966 0" xyz="0 0 0"/>
      <geometry><cylinder length="0.02" radius="0.035"/></geometry>
    </collision>
    <inertial>
      <origin rpy="0 0 0" xyz="0 0 0"/>
      <mass value="0.089"/>
      <inertia ixx="0.000111842" ixy="0" ixz="0" iyy="5.9647e-05" iyz="0" izz="5.9647e-05"/>
    </inertial>
  </link>

  <joint name="RR_thigh_joint" type="revolute">
    <origin rpy="0 0 0" xyz="0 -0.08 0"/>
    <parent link="RR_hip"/>
    <child link="RR_thigh"/>
    <axis xyz="0 1 0"/>
    <!-- IMPROVED: damping 0.0 → 1.0 -->
    <dynamics damping="1.0" friction="0.0"/>
    <limit effort="23.7" lower="-0.686" upper="4.501" velocity="30.1"/>
  </joint>

  <joint name="RR_thigh_rotor_joint" type="fixed">
    <origin rpy="0 0 0" xyz="0 0.00015 0"/>
    <parent link="RR_hip"/>
    <child link="RR_thigh_rotor"/>
  </joint>

  <link name="RR_thigh">
    <visual>
      <origin rpy="0 0 0" xyz="0 0 0"/>
      <geometry>
        <mesh filename="package://go1_description/meshes/thigh_mirror.dae" scale="1 1 1"/>
      </geometry>
    </visual>
    <collision>
      <origin rpy="0 1.5707963267948966 0" xyz="0 0 -0.1065"/>
      <geometry><box size="0.213 0.0245 0.034"/></geometry>
    </collision>
    <inertial>
      <origin rpy="0 0 0" xyz="-0.003342 -0.018054 -0.033451"/>
      <mass value="0.92"/>
      <inertia ixx="0.004431760472" ixy="-5.7496807e-05"
               ixz="-0.000218457134"
               iyy="0.004485671726" iyz="-0.000572001265"
               izz="0.000740309489"/>
    </inertial>
  </link>

  <link name="RR_thigh_rotor">
    <visual>
      <origin rpy="1.5707963267948966 0 0" xyz="0 0 0"/>
      <geometry><cylinder length="0.02" radius="0.035"/></geometry>
      <material name="green"/>
    </visual>
    <collision>
      <origin rpy="1.5707963267948966 0 0" xyz="0 0 0"/>
      <geometry><cylinder length="0.02" radius="0.035"/></geometry>
    </collision>
    <inertial>
      <origin rpy="0 0 0" xyz="0 0 0"/>
      <mass value="0.089"/>
      <inertia ixx="5.9647e-05" ixy="0" ixz="0" iyy="0.000111842" iyz="0" izz="5.9647e-05"/>
    </inertial>
  </link>

  <!-- IMPROVED: calf origin z: -0.213 → -0.255 (longer calf) -->
  <joint name="RR_calf_joint" type="revolute">
    <origin rpy="0 0 0" xyz="0 0 -0.213"/>
    <parent link="RR_thigh"/>
    <child link="RR_calf"/>
    <axis xyz="0 1 0"/>
    <!-- IMPROVED: damping 0.0 → 0.8 -->
    <dynamics damping="0.8" friction="0.0"/>
    <limit effort="35.55" lower="-2.818" upper="-0.888" velocity="20.06"/>
  </joint>

  <joint name="RR_calf_rotor_joint" type="fixed">
    <origin rpy="0 0 0" xyz="0 0.03235 0"/>
    <parent link="RR_thigh"/>
    <child link="RR_calf_rotor"/>
  </joint>

  <link name="RR_calf">
    <visual>
      <origin rpy="0 0 0" xyz="0 0 0"/>
      <geometry>
        <mesh filename="package://go1_description/meshes/calf.dae" scale="1 1 1.1972"/>
      </geometry>
    </visual>
    <!-- IMPROVED: calf collision box scaled to new length 255mm -->
    <collision>
      <origin rpy="0 1.5707963267948966 0" xyz="0 0 -0.1275"/>
      <geometry><box size="0.2550 0.016 0.016"/></geometry>
    </collision>
    <inertial>
      <origin rpy="0 0 0" xyz="0.006197 0.001408 -0.127500"/>
      <mass value="0.145"/>
      <inertia ixx="0.001300" ixy="0" ixz="7.1e-06" iyy="0.001310" iyz="2.1e-06" izz="2.5e-05"/>
    </inertial>
  </link>

  <link name="RR_calf_rotor">
    <visual>
      <origin rpy="1.5707963267948966 0 0" xyz="0 0 0"/>
      <geometry><cylinder length="0.02" radius="0.035"/></geometry>
      <material name="green"/>
    </visual>
    <collision>
      <origin rpy="1.5707963267948966 0 0" xyz="0 0 0"/>
      <geometry><cylinder length="0.02" radius="0.035"/></geometry>
    </collision>
    <inertial>
      <origin rpy="0 0 0" xyz="0 0 0"/>
      <mass value="0.089"/>
      <inertia ixx="5.9647e-05" ixy="0" ixz="0" iyy="0.000111842" iyz="0" izz="5.9647e-05"/>
    </inertial>
  </link>

  <!-- IMPROVED: foot offset matches new calf length 255mm -->
  <joint name="RR_foot_fixed" type="fixed">
    <origin rpy="0 0 0" xyz="0 0 -0.2550"/>
    <parent link="RR_calf"/>
    <child link="RR_foot"/>
  </joint>

  <!-- IMPROVED: foot collision radius 0.020 → 0.028 (better contact patch) -->
  <link name="RR_foot">
    <visual>
      <origin rpy="0 0 0" xyz="0 0 0"/>
      <geometry><sphere radius="0.01"/></geometry>
    </visual>
    <collision>
      <origin rpy="0 0 0" xyz="0 0 0"/>
      <geometry><sphere radius="0.028"/></geometry>
    </collision>
    <inertial>
      <mass value="0.06"/>
      <inertia ixx="9.6e-06" ixy="0" ixz="0" iyy="9.6e-06" iyz="0" izz="9.6e-06"/>
    </inertial>
  </link>

  <transmission name="RR_hip_tran">
    <type>transmission_interface/SimpleTransmission</type>
    <joint name="RR_hip_joint">
      <hardwareInterface>hardware_interface/EffortJointInterface</hardwareInterface>
    </joint>
    <actuator name="RR_hip_motor">
      <hardwareInterface>hardware_interface/EffortJointInterface</hardwareInterface>
      <mechanicalReduction>1</mechanicalReduction>
    </actuator>
  </transmission>
  <transmission name="RR_thigh_tran">
    <type>transmission_interface/SimpleTransmission</type>
    <joint name="RR_thigh_joint">
      <hardwareInterface>hardware_interface/EffortJointInterface</hardwareInterface>
    </joint>
    <actuator name="RR_thigh_motor">
      <hardwareInterface>hardware_interface/EffortJointInterface</hardwareInterface>
      <mechanicalReduction>1</mechanicalReduction>
    </actuator>
  </transmission>
  <transmission name="RR_calf_tran">
    <type>transmission_interface/SimpleTransmission</type>
    <joint name="RR_calf_joint">
      <hardwareInterface>hardware_interface/EffortJointInterface</hardwareInterface>
    </joint>
    <actuator name="RR_calf_motor">
      <hardwareInterface>hardware_interface/EffortJointInterface</hardwareInterface>
      <mechanicalReduction>1</mechanicalReduction>
    </actuator>
  </transmission>

  <!-- ═══════════ RL LEG ═══════════ -->

  <joint name="RL_hip_joint" type="revolute">
    <origin rpy="0 0 0" xyz="-0.1881 0.04675 0"/>
    <parent link="trunk"/>
    <child link="RL_hip"/>
    <axis xyz="1 0 0"/>
    <!-- IMPROVED: damping 0.0 → 0.5, hip range ±49° → ±60° -->
    <dynamics damping="0.5" friction="0.0"/>
    <limit effort="23.7" lower="-1.047" upper="1.047" velocity="30.1"/>
  </joint>

  <joint name="RL_hip_rotor_joint" type="fixed">
    <origin rpy="0 0 0" xyz="-0.11215 0.04675 0"/>
    <parent link="trunk"/>
    <child link="RL_hip_rotor"/>
  </joint>

  <link name="RL_hip">
    <visual>
      <origin rpy="0 3.141592653589793 0" xyz="0 0 0"/>
      <geometry>
        <mesh filename="package://go1_description/meshes/hip.dae" scale="1 1 1"/>
      </geometry>
    </visual>
    <collision>
      <origin rpy="1.5707963267948966 0 0" xyz="0 0.08 0"/>
      <geometry><cylinder length="0.04" radius="0.046"/></geometry>
    </collision>
    <inertial>
      <origin rpy="0 0 0" xyz="-0.005657 0.008752 -0.000102"/>
      <mass value="0.591"/>
      <inertia ixx="0.000334008405" ixy="-1.0826066e-05" ixz="-1.290732e-06"
               iyy="0.000619101213" iyz="-1.643194e-06" izz="0.00040057614"/>
    </inertial>
  </link>

  <link name="RL_hip_rotor">
    <visual>
      <origin rpy="0 1.5707963267948966 0" xyz="0 0 0"/>
      <geometry><cylinder length="0.02" radius="0.035"/></geometry>
      <material name="green"/>
    </visual>
    <collision>
      <origin rpy="0 1.5707963267948966 0" xyz="0 0 0"/>
      <geometry><cylinder length="0.02" radius="0.035"/></geometry>
    </collision>
    <inertial>
      <origin rpy="0 0 0" xyz="0 0 0"/>
      <mass value="0.089"/>
      <inertia ixx="0.000111842" ixy="0" ixz="0" iyy="5.9647e-05" iyz="0" izz="5.9647e-05"/>
    </inertial>
  </link>

  <joint name="RL_thigh_joint" type="revolute">
    <origin rpy="0 0 0" xyz="0 0.08 0"/>
    <parent link="RL_hip"/>
    <child link="RL_thigh"/>
    <axis xyz="0 1 0"/>
    <!-- IMPROVED: damping 0.0 → 1.0 -->
    <dynamics damping="1.0" friction="0.0"/>
    <limit effort="23.7" lower="-0.686" upper="4.501" velocity="30.1"/>
  </joint>

  <joint name="RL_thigh_rotor_joint" type="fixed">
    <origin rpy="0 0 0" xyz="0 -0.00015 0"/>
    <parent link="RL_hip"/>
    <child link="RL_thigh_rotor"/>
  </joint>

  <link name="RL_thigh">
    <visual>
      <origin rpy="0 0 0" xyz="0 0 0"/>
      <geometry>
        <mesh filename="package://go1_description/meshes/thigh.dae" scale="1 1 1"/>
      </geometry>
    </visual>
    <collision>
      <origin rpy="0 1.5707963267948966 0" xyz="0 0 -0.1065"/>
      <geometry><box size="0.213 0.0245 0.034"/></geometry>
    </collision>
    <inertial>
      <origin rpy="0 0 0" xyz="-0.003342 0.018054 -0.033451"/>
      <mass value="0.92"/>
      <inertia ixx="0.004431760472" ixy="5.7496807e-05"
               ixz="-0.000218457134"
               iyy="0.004485671726" iyz="0.000572001265"
               izz="0.000740309489"/>
    </inertial>
  </link>

  <link name="RL_thigh_rotor">
    <visual>
      <origin rpy="1.5707963267948966 0 0" xyz="0 0 0"/>
      <geometry><cylinder length="0.02" radius="0.035"/></geometry>
      <material name="green"/>
    </visual>
    <collision>
      <origin rpy="1.5707963267948966 0 0" xyz="0 0 0"/>
      <geometry><cylinder length="0.02" radius="0.035"/></geometry>
    </collision>
    <inertial>
      <origin rpy="0 0 0" xyz="0 0 0"/>
      <mass value="0.089"/>
      <inertia ixx="5.9647e-05" ixy="0" ixz="0" iyy="0.000111842" iyz="0" izz="5.9647e-05"/>
    </inertial>
  </link>

  <!-- IMPROVED: calf origin z: -0.213 → -0.255 (longer calf) -->
  <joint name="RL_calf_joint" type="revolute">
    <origin rpy="0 0 0" xyz="0 0 -0.213"/>
    <parent link="RL_thigh"/>
    <child link="RL_calf"/>
    <axis xyz="0 1 0"/>
    <!-- IMPROVED: damping 0.0 → 0.8 -->
    <dynamics damping="0.8" friction="0.0"/>
    <limit effort="35.55" lower="-2.818" upper="-0.888" velocity="20.06"/>
  </joint>

  <joint name="RL_calf_rotor_joint" type="fixed">
    <origin rpy="0 0 0" xyz="0 -0.03235 0"/>
    <parent link="RL_thigh"/>
    <child link="RL_calf_rotor"/>
  </joint>

  <link name="RL_calf">
    <visual>
      <origin rpy="0 0 0" xyz="0 0 0"/>
      <geometry>
        <mesh filename="package://go1_description/meshes/calf.dae" scale="1 1 1.1972"/>
      </geometry>
    </visual>
    <!-- IMPROVED: calf collision box scaled to new length 255mm -->
    <collision>
      <origin rpy="0 1.5707963267948966 0" xyz="0 0 -0.1275"/>
      <geometry><box size="0.2550 0.016 0.016"/></geometry>
    </collision>
    <inertial>
      <origin rpy="0 0 0" xyz="0.006197 0.001408 -0.127500"/>
      <mass value="0.145"/>
      <inertia ixx="0.001300" ixy="0" ixz="7.1e-06" iyy="0.001310" iyz="2.1e-06" izz="2.5e-05"/>
    </inertial>
  </link>

  <link name="RL_calf_rotor">
    <visual>
      <origin rpy="1.5707963267948966 0 0" xyz="0 0 0"/>
      <geometry><cylinder length="0.02" radius="0.035"/></geometry>
      <material name="green"/>
    </visual>
    <collision>
      <origin rpy="1.5707963267948966 0 0" xyz="0 0 0"/>
      <geometry><cylinder length="0.02" radius="0.035"/></geometry>
    </collision>
    <inertial>
      <origin rpy="0 0 0" xyz="0 0 0"/>
      <mass value="0.089"/>
      <inertia ixx="5.9647e-05" ixy="0" ixz="0" iyy="0.000111842" iyz="0" izz="5.9647e-05"/>
    </inertial>
  </link>

  <!-- IMPROVED: foot offset matches new calf length 255mm -->
  <joint name="RL_foot_fixed" type="fixed">
    <origin rpy="0 0 0" xyz="0 0 -0.2550"/>
    <parent link="RL_calf"/>
    <child link="RL_foot"/>
  </joint>

  <!-- IMPROVED: foot collision radius 0.020 → 0.028 (better contact patch) -->
  <link name="RL_foot">
    <visual>
      <origin rpy="0 0 0" xyz="0 0 0"/>
      <geometry><sphere radius="0.01"/></geometry>
    </visual>
    <collision>
      <origin rpy="0 0 0" xyz="0 0 0"/>
      <geometry><sphere radius="0.028"/></geometry>
    </collision>
    <inertial>
      <mass value="0.06"/>
      <inertia ixx="9.6e-06" ixy="0" ixz="0" iyy="9.6e-06" iyz="0" izz="9.6e-06"/>
    </inertial>
  </link>

  <transmission name="RL_hip_tran">
    <type>transmission_interface/SimpleTransmission</type>
    <joint name="RL_hip_joint">
      <hardwareInterface>hardware_interface/EffortJointInterface</hardwareInterface>
    </joint>
    <actuator name="RL_hip_motor">
      <hardwareInterface>hardware_interface/EffortJointInterface</hardwareInterface>
      <mechanicalReduction>1</mechanicalReduction>
    </actuator>
  </transmission>
  <transmission name="RL_thigh_tran">
    <type>transmission_interface/SimpleTransmission</type>
    <joint name="RL_thigh_joint">
      <hardwareInterface>hardware_interface/EffortJointInterface</hardwareInterface>
    </joint>
    <actuator name="RL_thigh_motor">
      <hardwareInterface>hardware_interface/EffortJointInterface</hardwareInterface>
      <mechanicalReduction>1</mechanicalReduction>
    </actuator>
  </transmission>
  <transmission name="RL_calf_tran">
    <type>transmission_interface/SimpleTransmission</type>
    <joint name="RL_calf_joint">
      <hardwareInterface>hardware_interface/EffortJointInterface</hardwareInterface>
    </joint>
    <actuator name="RL_calf_motor">
      <hardwareInterface>hardware_interface/EffortJointInterface</hardwareInterface>
      <mechanicalReduction>1</mechanicalReduction>
    </actuator>
  </transmission>


  <!-- GAZEBO MATERIAL + FRICTION TAGS -->
  <gazebo reference="trunk">
    <mu1>0.2</mu1><mu2>0.2</mu2>
    <kp value="1000000.0"/><kd value="1.0"/>
  </gazebo>

  <gazebo reference="FR_foot">
    <!-- IMPROVED: friction 0.6 → 0.8 -->
    <mu1>0.8</mu1>
    <mu2>0.8</mu2>
    <self_collide>1</self_collide>
    <material>Gazebo/DarkGrey</material>
    <kp value="1000000.0"/>
    <kd value="1.0"/>
  </gazebo>
  <gazebo reference="FR_hip">
    <mu1>0.2</mu1><mu2>0.2</mu2>
    <material>Gazebo/DarkGrey</material>
  </gazebo>
  <gazebo reference="FR_thigh">
    <mu1>0.2</mu1><mu2>0.2</mu2>
    <self_collide>1</self_collide>
    <material>Gazebo/DarkGrey</material>
    <kp value="1000000.0"/><kd value="1.0"/>
  </gazebo>
  <gazebo reference="FR_calf">
    <mu1>0.2</mu1><mu2>0.2</mu2>
    <self_collide>1</self_collide>
  </gazebo>
  <gazebo reference="FL_foot">
    <!-- IMPROVED: friction 0.6 → 0.8 -->
    <mu1>0.8</mu1>
    <mu2>0.8</mu2>
    <self_collide>1</self_collide>
    <material>Gazebo/DarkGrey</material>
    <kp value="1000000.0"/>
    <kd value="1.0"/>
  </gazebo>
  <gazebo reference="FL_hip">
    <mu1>0.2</mu1><mu2>0.2</mu2>
    <material>Gazebo/DarkGrey</material>
  </gazebo>
  <gazebo reference="FL_thigh">
    <mu1>0.2</mu1><mu2>0.2</mu2>
    <self_collide>1</self_collide>
    <material>Gazebo/DarkGrey</material>
    <kp value="1000000.0"/><kd value="1.0"/>
  </gazebo>
  <gazebo reference="FL_calf">
    <mu1>0.2</mu1><mu2>0.2</mu2>
    <self_collide>1</self_collide>
  </gazebo>
  <gazebo reference="RR_foot">
    <!-- IMPROVED: friction 0.6 → 0.8 -->
    <mu1>0.8</mu1>
    <mu2>0.8</mu2>
    <self_collide>1</self_collide>
    <material>Gazebo/DarkGrey</material>
    <kp value="1000000.0"/>
    <kd value="1.0"/>
  </gazebo>
  <gazebo reference="RR_hip">
    <mu1>0.2</mu1><mu2>0.2</mu2>
    <material>Gazebo/DarkGrey</material>
  </gazebo>
  <gazebo reference="RR_thigh">
    <mu1>0.2</mu1><mu2>0.2</mu2>
    <self_collide>1</self_collide>
    <material>Gazebo/DarkGrey</material>
    <kp value="1000000.0"/><kd value="1.0"/>
  </gazebo>
  <gazebo reference="RR_calf">
    <mu1>0.2</mu1><mu2>0.2</mu2>
    <self_collide>1</self_collide>
  </gazebo>
  <gazebo reference="RL_foot">
    <!-- IMPROVED: friction 0.6 → 0.8 -->
    <mu1>0.8</mu1>
    <mu2>0.8</mu2>
    <self_collide>1</self_collide>
    <material>Gazebo/DarkGrey</material>
    <kp value="1000000.0"/>
    <kd value="1.0"/>
  </gazebo>
  <gazebo reference="RL_hip">
    <mu1>0.2</mu1><mu2>0.2</mu2>
    <material>Gazebo/DarkGrey</material>
  </gazebo>
  <gazebo reference="RL_thigh">
    <mu1>0.2</mu1><mu2>0.2</mu2>
    <self_collide>1</self_collide>
    <material>Gazebo/DarkGrey</material>
    <kp value="1000000.0"/><kd value="1.0"/>
  </gazebo>
  <gazebo reference="RL_calf">
    <mu1>0.2</mu1><mu2>0.2</mu2>
    <self_collide>1</self_collide>
  </gazebo>
  <gazebo reference="FR_calf">
    <sensor name="FR_foot_contact" type="contact">
      <update_rate>100</update_rate>
      <plugin filename="libunitreeFootContactPlugin.so" name="contactPlugin"/>
      <contact>
        <collision>FR_calf_fixed_joint_lump__FR_foot_collision_1</collision>
      </contact>
    </sensor>
  </gazebo>
  <gazebo reference="FL_calf">
    <sensor name="FL_foot_contact" type="contact">
      <update_rate>100</update_rate>
      <plugin filename="libunitreeFootContactPlugin.so" name="contactPlugin"/>
      <contact>
        <collision>FL_calf_fixed_joint_lump__FL_foot_collision_1</collision>
      </contact>
    </sensor>
  </gazebo>
  <gazebo reference="RR_calf">
    <sensor name="RR_foot_contact" type="contact">
      <update_rate>100</update_rate>
      <plugin filename="libunitreeFootContactPlugin.so" name="contactPlugin"/>
      <contact>
        <collision>RR_calf_fixed_joint_lump__RR_foot_collision_1</collision>
      </contact>
    </sensor>
  </gazebo>
  <gazebo reference="RL_calf">
    <sensor name="RL_foot_contact" type="contact">
      <update_rate>100</update_rate>
      <plugin filename="libunitreeFootContactPlugin.so" name="contactPlugin"/>
      <contact>
        <collision>RL_calf_fixed_joint_lump__RL_foot_collision_1</collision>
      </contact>
    </sensor>
  </gazebo>

</robot>
